Workbook
Name categories: [1]Settings!$I$7:$I$15
Name catSymbols: [1]Settings!$J$7:$J$15
Name Slicer_Department: #N/A
Name Slicer_Department1: #N/A
Name Slicer_Department2: #N/A
Name Slicer_Location: #N/A
Name Slicer_Location1: #N/A
Name Slicer_Location2: #N/A

Sheet FResult Record
C3: 2023 | J3: 2024 | Q3: 2025
C4: Performance | E4: Poor | F4: Average | G4: High | J4: Performance | L4: Poor | M4: Average | N4: High | Q4: Performance | S4: Poor | T4: Average | U4: High
C5: Potin | D5: High | E5: =COUNTIF(Table6[Gird Zone],"3A") -> 3 | F5: =COUNTIF(Table6[Gird Zone],"3B") -> 3 | G5: =COUNTIF(Table6[Gird Zone],"3C") -> 23 | J5: Potin | K5: High | L5: =COUNTIF(Table7[Grid Zone],"3A") -> 0 | M5: =COUNTIF(Table7[Grid Zone],"3B") -> 1 | N5: =COUNTIF(Table7[Grid Zone],"3C") -> 36 | Q5: Potin | R5: High | S5: =COUNTIF(Table8[[Grid Zone ]],"3A") -> 0 | T5: =COUNTIF(Table8[[Grid Zone ]],"3B") -> 3 | U5: =COUNTIF(Table8[[Grid Zone ]],"3C") -> 56
D6: Medium | E6: =COUNTIF(Table6[Gird Zone],"2A") -> 30 | F6: =COUNTIF(Table6[Gird Zone],"2B") -> 52 | G6: =COUNTIF(Table6[Gird Zone],"2C") -> 5 | K6: Medium | L6: =COUNTIF(Table7[Grid Zone],"2A") -> 16 | M6: =COUNTIF(Table7[Grid Zone],"2B") -> 84 | N6: =COUNTIF(Table7[Grid Zone],"2C") -> 2 | R6: Medium | S6: =COUNTIF(Table8[[Grid Zone ]],"2A") -> 21 | T6: =COUNTIF(Table8[[Grid Zone ]],"2B") -> 97 | U6: =COUNTIF(Table8[[Grid Zone ]],"2C") -> 11
D7: Low | E7: =COUNTIF(Table6[Gird Zone],"1A") -> 2 | F7: =COUNTIF(Table6[Gird Zone],"1B") -> 0 | G7: =COUNTIF(Table6[Gird Zone],"1C") -> 0 | K7: Low | L7: =COUNTIF(Table7[Grid Zone],"1A") -> 3 | M7: =COUNTIF(Table7[Grid Zone],"1B") -> 0 | N7: =COUNTIF(Table7[Grid Zone],"1C") -> 0 | R7: Low | S7: =COUNTIF(Table8[[Grid Zone ]],"1A") -> 1 | T7: =COUNTIF(Table8[[Grid Zone ]],"1B") -> 0 | U7: =COUNTIF(Table8[[Grid Zone ]],"1C") -> 0

Sheet Overall Evaluation
E3: Exceptional | F3: 4.6 - 5 | G3: Weighted Score | H3: Performance Zone | J3: Performance Zone
E4: exeed expectation | F4: 3.6 - 4.5 | G4: أقل من 3.0 | H4: Poor | J4: Poor | M4: 1-3.4
E5: Meet | F5: 3 - 3.5 | G5: 3.0 إلى أقل من 3.8 | H5: Average | J5: Average | M5: 3.5-4. | P5: من 0 الى 3.4
E6: below | F6: 2 - 2.9 | G6: 3.8 فأكثر | H6: High | J6: High
E7: Need | F7: 0-1.99
A9: Employee Performance Evaluation
H10: Performance
A11: Num | B11: EMP ID | C11: Name | D11: Joining date | E11: Employee Location | F11: Position | G11: Depatrment | H11: OBJ 2023 | I11: Comp 23 | J11: overall 23 | K11: OBJ 2024 | L11: Comp 24 | M11: overall 24 | N11: OBJ 2025 | O11: Comp 25 | P11: overall 25 | Q11: Performance Average | R11: Perforamnce ZONE 25 | S11: Grid Location | T11: overall 23 | U11: Grid Location 23 | V11: overall 24 | W11: Grid Location 24
A12: 1 | B12: 31260 | C12: ='[2]Evalution 25'!B2 -> Abdulaziz Abdullah Abdulaziz Al Zehairi | D12: 44559 | E12: ='[2]Evalution 25'!C2 -> Riyadh | F12: ='[2]Evalution 25'!E2 -> Runner Driver | G12: ='[2]Evalution 25'!D2 -> Admin | H12: ='[2]Evalutaion 23'!G2 -> 5 | I12: ='[2]Evalutaion 23'!H2 -> 5 | J12: =IF(COUNT(H12:I12)>0,AVERAGEIF(H12:I12,">=0"), IF(AND(ISNUMBER(D12),D12<=DATE(2023,12,31)),"NR","NA")) -> 5 | K12: ='[2]Evalutaion 24'!G2 -> 5 | L12: ='[2]Evalutaion 24'!H2 -> 5 | M12: =IF(COUNT(K12:L12)>0,AVERAGEIF(K12:L12,">=0"), IF(AND(ISNUMBER(D12),D12<=DATE(2024,12,31)),"NR","NA")) -> 5 | N12: ='[2]Evalution 25'!G2 -> 3 | O12: ='[2]Evalution 25'!H2 -> 4 | P12: =IF(COUNT(N12:O12)>0,AVERAGEIF(N12:O12,">=0"), IF(AND(ISNUMBER(D12),D12<=DATE(2025,12,31)),"NR","NA")) -> 3.5 | Q12: =AVERAGE(J12:P12) -> 4.3571429 | R12: =IF(P12="","", IF(OR(P12="NR",P12="NA"),"NA", IF(P12<3.4,"Poor", IF(P12<4.4,"Average","High") ))) -> Average | S12: =IFERROR( _xlfn.XLOOKUP(P12,[2]Result!$A$7:$A$15,[2]Result!$C$7:$C$15,"Out of range",-1),"N/A") -> 2C | T12: =IF($D12>DATE(2023,12,31),"NA",IF(J12="","NR",J12)) -> 5 | U12: {=IF(OR(J12="NA",J12="NR",ISBLANK(J12)),J12,IFERROR(INDEX([2]Result!$C$7:$C$15,MATCH(1,(J12>=[2]Result!$A$7:$A$15)*(J12<=[2]Result!$B$7:$B$15),0)), "NA"))} -> 3C | V12: =IF($D12>DATE(2024,12,31),"NA",IF(M12="","NR",M12)) -> 5 | W12: {=IF(OR(M12="NA",M12="NR",ISBLANK(M12)),M12,IFERROR(INDEX([2]Result!$C$7:$C$15,MATCH(1,(M12>=[2]Result!$A$7:$A$15)*(M12<=[2]Result!$B$7:$B$15),0)), "NA"))} -> 3C
A13: 2 | B13: 50169 | C13: ='[2]Evalution 25'!B3 -> Abdulaziz Obaid Meshan Alharbi | D13: 45698 | E13: ='[2]Evalution 25'!C3 -> Riyadh | F13: ='[2]Evalution 25'!E3 -> HR Executive | G13: ='[2]Evalution 25'!D3 -> HR | H13: - | I13: - | J13: =IF(COUNT(H13:I13)>0,AVERAGEIF(H13:I13,">=0"), IF(AND(ISNUMBER(D13),D13<=DATE(2023,12,31)),"NR","NA")) -> NA | K13: - | L13: - | M13: =IF(COUNT(K13:L13)>0,AVERAGEIF(K13:L13,">=0"), IF(AND(ISNUMBER(D13),D13<=DATE(2024,12,31)),"NR","NA")) -> NA | N13: ='[2]Evalution 25'!G3 -> 3.4 | O13: ='[2]Evalution 25'!H3 -> 3.3 | P13: =IF(COUNT(N13:O13)>0,AVERAGEIF(N13:O13,">=0"), IF(AND(ISNUMBER(D13),D13<=DATE(2025,12,31)),"NR","NA")) -> 3.35 | Q13: =AVERAGE(J13,M13,P13,) -> 1.675 | R13: =IF(P13="","", IF(OR(P13="NR",P13="NA"),"NA", IF(P13<3,"Poor", IF(P13<3.8,"Average","High") ))) -> Average | S13: =IFERROR( _xlfn.XLOOKUP(Q13,[2]Result!$A$7:$A$15,[2]Result!$C$7:$C$15,"Out of range",-1),"N/A") -> 1C | T13: =IF($D13>DATE(2023,12,31),"NA",IF(J13="","NR",J13)) -> NA | U13: {=IF(OR(J13="NA",J13="NR",ISBLANK(J13)),J13,IFERROR(INDEX([2]Result!$C$7:$C$15,MATCH(1,(J13>=[2]Result!$A$7:$A$15)*(J13<=[2]Result!$B$7:$B$15),0)), "NA"))} -> NA | V13: =IF($D13>DATE(2024,12,31),"NA",IF(M13="","NR",M13)) -> NA | W13: {=IF(OR(M13="NA",M13="NR",ISBLANK(M13)),M13,IFERROR(INDEX([2]Result!$C$7:$C$15,MATCH(1,(M13>=[2]Result!$A$7:$A$15)*(M13<=[2]Result!$B$7:$B$15),0)), "NA"))} -> NA
A14: 3 | B14: 4756 | C14: ='[2]Evalution 25'!B4 -> Abdulkader Abbasbhai Sukhsarwala | D14: 43625 | E14: ='[2]Evalution 25'!C4 -> Dubai | F14: ='[2]Evalution 25'!E4 -> Senior Digital Yield Analyst | G14: ='[2]Evalution 25'!D4 -> Client Growth | H14: ='[2]Evalutaion 23'!G3 -> 3.9 | I14: ='[2]Evalutaion 23'!H3 -> 3.8 | J14: =IF(COUNT(H14:I14)>0,AVERAGEIF(H14:I14,">=0"), IF(AND(ISNUMBER(D14),D14<=DATE(2023,12,31)),"NR","NA")) -> 3.85 | K14: ='[2]Evalutaion 24'!G3 -> 4.4 | L14: ='[2]Evalutaion 24'!H3 -> 3.8 | M14: =IF(COUNT(K14:L14)>0,AVERAGEIF(K14:L14,">=0"), IF(AND(ISNUMBER(D14),D14<=DATE(2024,12,31)),"NR","NA")) -> 4.1 | N14: ='[2]Evalution 25'!G4 -> 4.6 | O14: ='[2]Evalution 25'!H4 -> 4.8 | P14: =IF(COUNT(N14:O14)>0,AVERAGEIF(N14:O14,">=0"), IF(AND(ISNUMBER(D14),D14<=DATE(2025,12,31)),"NR","NA")) -> 4.7 | Q14: =AVERAGE(J14,M14,P14,) -> 3.1625 | R14: =IF(P14="","", IF(OR(P14="NR",P14="NA"),"NA", IF(P14<3,"Poor", IF(P14<3.8,"Average","High") ))) -> High | S14: =IFERROR( _xlfn.XLOOKUP(Q14,[2]Result!$A$7:$A$15,[2]Result!$C$7:$C$15,"Out of range",-1),"N/A") -> 2C | T14: =IF($D14>DATE(2023,12,31),"NA",IF(J14="","NR",J14)) -> 3.85 | U14: {=IF(OR(J14="NA",J14="NR",ISBLANK(J14)),J14,IFERROR(INDEX([2]Result!$C$7:$C$15,MATCH(1,(J14>=[2]Result!$A$7:$A$15)*(J14<=[2]Result!$B$7:$B$15),0)), "NA"))} -> 3A | V14: =IF($D14>DATE(2024,12,31),"NA",IF(M14="","NR",M14)) -> 4.1 | W14: {=IF(OR(M14="NA",M14="NR",ISBLANK(M14)),M14,IFERROR(INDEX([2]Result!$C$7:$C$15,MATCH(1,(M14>=[2]Result!$A$7:$A$15)*(M14<=[2]Result!$B$7:$B$15),0)), "NA"))} -> 3B
A15: 4 | B15: 50496 | C15: ='[2]Evalution 25'!B5 -> George George | D15: 45788 | E15: ='[2]Evalution 25'!C5 -> Dubai | F15: ='[2]Evalution 25'!E5 -> Financial Controller-MMS | G15: ='[2]Evalution 25'!D5 -> Finance | H15: - | I15: - | J15: =IF(COUNT(H15:I15)>0,AVERAGEIF(H15:I15,">=0"), IF(AND(ISNUMBER(D15),D15<=DATE(2023,12,31)),"NR","NA")) -> NA | K15: - | L15: - | M15: =IF(COUNT(K15:L15)>0,AVERAGEIF(K15:L15,">=0"), IF(AND(ISNUMBER(D15),D15<=DATE(2024,12,31)),"NR","NA")) -> NA | N15: ='[2]Evalution 25'!G5 -> 4.8 | O15: ='[2]Evalution 25'!H5 -> 4.8 | P15: =IF(COUNT(N15:O15)>0,AVERAGEIF(N15:O15,">=0"), IF(AND(ISNUMBER(D15),D15<=DATE(2025,12,31)),"NR","NA")) -> 4.8 | Q15: =AVERAGE(J15,M15,P15,) -> 2.4 | R15: =IF(P15="","", IF(OR(P15="NR",P15="NA"),"NA", IF(P15<3,"Poor", IF(P15<3.8,"Average","High") ))) -> High | S15: =IFERROR( _xlfn.XLOOKUP(Q15,[2]Result!$A$7:$A$15,[2]Result!$C$7:$C$15,"Out of range",-1),"N/A") -> 2A | T15: =IF($D15>DATE(2023,12,31),"NA",IF(J15="","NR",J15)) -> NA | U15: {=IF(OR(J15="NA",J15="NR",ISBLANK(J15)),J15,IFERROR(INDEX([2]Result!$C$7:$C$15,MATCH(1,(J15>=[2]Result!$A$7:$A$15)*(J15<=[2]Result!$B$7:$B$15),0)), "NA"))} -> NA | V15: =IF($D15>DATE(2024,12,31),"NA",IF(M15="","NR",M15)) -> NA | W15: {=IF(OR(M15="NA",M15="NR",ISBLANK(M15)),M15,IFERROR(INDEX([2]Result!$C$7:$C$15,MATCH(1,(M15>=[2]Result!$A$7:$A$15)*(M15<=[2]Result!$B$7:$B$15),0)), "NA"))} -> NA
A16: 5 | B16: 48121 | C16: ='[2]Evalution 25'!B6 -> Abdullah Mohammed Abutaleb | D16: 45194 | E16: ='[2]Evalution 25'!C6 -> Riyadh | F16: ='[2]Evalution 25'!E6 -> Marketing Manager | G16: ='[2]Evalution 25'!D6 -> Marketing | H16: ='[2]Evalutaion 23'!G4 -> 3 | I16: ='[2]Evalutaion 23'!H4 -> 3.7 | J16: =IF(COUNT(H16:I16)>0,AVERAGEIF(H16:I16,">=0"), IF(AND(ISNUMBER(D16),D16<=DATE(2023,12,31)),"NR","NA")) -> 3.35 | K16: ='[2]Evalutaion 24'!G4 -> 3.3 | L16: ='[2]Evalutaion 24'!H4 -> 3.8 | M16: =IF(COUNT(K16:L16)>0,AVERAGEIF(K16:L16,">=0"), IF(AND(ISNUMBER(D16),D16<=DATE(2024,12,31)),"NR","NA")) -> 3.55 | N16: ='[2]Evalution 25'!G6 -> 4.2 | O16: ='[2]Evalution 25'!H6 -> 4.2 | P16: =IF(COUNT(N16:O16)>0,AVERAGEIF(N16:O16,">=0"), IF(AND(ISNUMBER(D16),D16<=DATE(2025,12,31)),"NR","NA")) -> 4.2 | Q16: =AVERAGE(J16,M16,P16,) -> 2.775 | R16: =IF(P16="","", IF(OR(P16="NR",P16="NA"),"NA", IF(P16<3,"Poor", IF(P16<3.8,"Average","High") ))) -> High | S16: =IFERROR( _xlfn.XLOOKUP(Q16,[2]Result!$A$7:$A$15,[2]Result!$C$7:$C$15,"Out of range",-1),"N/A") -> 2B | T16: =IF($D16>DATE(2023,12,31),"NA",IF(J16="","NR",J16)) -> 3.35 | U16: {=IF(OR(J16="NA",J16="NR",ISBLANK(J16)),J16,IFERROR(INDEX([2]Result!$C$7:$C$15,MATCH(1,(J16>=[2]Result!$A$7:$A$15)*(J16<=[2]Result!$B$7:$B$15),0)), "NA"))} -> 2C | V16: =IF($D16>DATE(2024,12,31),"NA",IF(M16="","NR",M16)) -> 3.55 | W16: {=IF(OR(M16="NA",M16="NR",ISBLANK(M16)),M16,IFERROR(INDEX([2]Result!$C$7:$C$15,MATCH(1,(M16>=[2]Result!$A$7:$A$15)*(M16<=[2]Result!$B$7:$B$15),0)), "NA"))} -> NA
A17: 6 | B17: 10848 | C17: ='[2]Evalution 25'!B7 -> Abir Kharsa | D17: 44332 | E17: ='[2]Evalution 25'!C7 -> Dubai | F17: ='[2]Evalution 25'!E7 -> Senior Traffic Executive | G17: ='[2]Evalution 25'!D7 -> Traffic | H17: ='[2]Evalutaion 23'!G5 -> 4.6 | I17: ='[2]Evalutaion 23'!H5 -> 5 | J17: =IF(COUNT(H17:I17)>0,AVERAGEIF(H17:I17,">=0"), IF(AND(ISNUMBER(D17),D17<=DATE(2023,12,31)),"NR","NA")) -> 4.8 | K17: ='[2]Evalutaion 24'!G5 -> 4.8 | L17: ='[2]Evalutaion 24'!H5 -> 4.7 | M17: =IF(COUNT(K17:L17)>0,AVERAGEIF(K17:L17,">=0"), IF(AND(ISNUMBER(D17),D17<=DATE(2024,12,31)),"NR","NA")) -> 4.75 | N17: ='[2]Evalution 25'!G7 -> 5 | O17: ='[2]Evalution 25'!H7 -> 5 | P17: =IF(COUNT(N17:O17)>0,AVERAGEIF(N17:O17,">=0"), IF(AND(ISNUMBER(D17),D17<=DATE(2025,12,31)),"NR","NA")) -> 5 | Q17: =AVERAGE(J17,M17,P17,) -> 3.6375 | R17: =IF(P17="","", IF(OR(P17="NR",P17="NA"),"NA", IF(P17<3,"Poor", IF(P17<3.8,"Average","High") ))) -> High | S17: =IFERROR( _xlfn.XLOOKUP(Q17,[2]Result!$A$7:$A$15,[2]Result!$C$7:$C$15,"Out of range",-1),"N/A") -> 3A | T17: =IF($D17>DATE(2023,12,31),"NA",IF(J17="","NR",J17)) -> 4.8 | U17: {=IF(OR(J17="NA",J17="NR",ISBLANK(J17)),J17,IFERROR(INDEX([2]Result!$C$7:$C$15,MATCH(1,(J17>=[2]Result!$A$7:$A$15)*(J17<=[2]Result!$B$7:$B$15),0)), "NA"))} -> 3C | V17: =IF($D17>DATE(2024,12,31),"NA",IF(M17="","NR",M17)) -> 4.75 | W17: {=IF(OR(M17="NA",M17="NR",ISBLANK(M17)),M17,IFERROR(INDEX([2]Result!$C$7:$C$15,MATCH(1,(M17>=[2]Result!$A$7:$A$15)*(M17<=[2]Result!$B$7:$B$15),0)), "NA"))} -> 3C
A18: 7 | B18: 6557 | C18: ='[2]Evalution 25'!B8 -> Adel Mohamed Adeeb Abou Elnasr Mohamed | D18: 44228 | E18: ='[2]Evalution 25'!C8 -> Cairo | F18: ='[2]Evalution 25'!E8 -> Client Service Senior Supervisor | G18: ='[2]Evalution 25'!D8 -> Agency Partnerships | H18: ='[2]Evalutaion 23'!G6 -> 4.3 | I18: ='[2]Evalutaion 23'!H6 -> 4.3 | J18: =IF(COUNT(H18:I18)>0,AVERAGEIF(H18:I18,">=0"), IF(AND(ISNUMBER(D18),D18<=DATE(2023,12,31)),"NR","NA")) -> 4.3 | K18: ='[2]Evalutaion 24'!G6 -> 4 | L18: ='[2]Evalutaion 24'!H6 -> 4.3 | M18: =IF(COUNT(K18:L18)>0,AVERAGEIF(K18:L18,">=0"), IF(AND(ISNUMBER(D18),D18<=DATE(2024,12,31)),"NR","NA")) -> 4.15 | N18: ='[2]Evalution 25'!G8 -> 4 | O18: ='[2]Evalution 25'!H8 -> 3.8 | P18: =IF(COUNT(N18:O18)>0,AVERAGEIF(N18:O18,">=0"), IF(AND(ISNUMBER(D18),D18<=DATE(2025,12,31)),"NR","NA")) -> 3.9 | Q18: =AVERAGE(J18,M18,P18,) -> 3.0875 | R18: =IF(P18="","", IF(OR(P18="NR",P18="NA"),"NA", IF(P18<3,"Poor", IF(P18<3.8,"Average","High") ))) -> High | S18: =IFERROR( _xlfn.XLOOKUP(Q18,[2]Result!$A$7:$A$15,[2]Result!$C$7:$C$15,"Out of range",-1),"N/A") -> 2B | T18: =IF($D18>DATE(2023,12,31),"NA",IF(J18="","NR",J18)) -> 4.3 | U18: {=IF(OR(J18="NA",J18="NR",ISBLANK(J18)),J18,IFERROR(INDEX([2]Result!$C$7:$C$15,MATCH(1,(J18>=[2]Result!$A$7:$A$15)*(J18<=[2]Result!$B$7:$B$15),0)), "NA"))} -> 3B | V18: =IF($D18>DATE(2024,12,31),"NA",IF(M18="","NR",M18)) -> 4.15 | W18: {=IF(OR(M18="NA",M18="NR",ISBLANK(M18)),M18,IFERROR(INDEX([2]Result!$C$7:$C$15,MATCH(1,(M18>=[2]Result!$A$7:$A$15)*(M18<=[2]Result!$B$7:$B$15),0)), "NA"))} -> 3B
A19: 8 | B19: 4984 | C19: ='[2]Evalution 25'!B9 -> Adriana Nicolas Khater Verdin | D19: 43835 | E19: ='[2]Evalution 25'!C9 -> Dubai | F19: ='[2]Evalution 25'!E9 -> Content Solutions Senior Executive | G19: ='[2]Evalution 25'!D9 -> Content Solutions | H19: ='[2]Evalutaion 23'!G7 -> 4 | I19: ='[2]Evalutaion 23'!H7 -> 3.7 | J19: =IF(COUNT(H19:I19)>0,AVERAGEIF(H19:I19,">=0"), IF(AND(ISNUMBER(D19),D19<=DATE(2023,12,31)),"NR","NA")) -> 3.85 | K19: ='[2]Evalutaion 24'!G7 -> 5 | L19: ='[2]Evalutaion 24'!H7 -> 5 | M19: =IF(COUNT(K19:L19)>0,AVERAGEIF(K19:L19,">=0"), IF(AND(ISNUMBER(D19),D19<=DATE(2024,12,31)),"NR","NA")) -> 5 | N19: ='[2]Evalution 25'!G9 -> 4 | O19: ='[2]Evalution 25'!H9 -> 4 | P19: =IF(COUNT(N19:O19)>0,AVERAGEIF(N19:O19,">=0"), IF(AND(ISNUMBER(D19),D19<=DATE(2025,12,31)),"NR","NA")) -> 4 | Q19: =AVERAGE(J19,M19,P19,) -> 3.2125 | R19: =IF(P19="","", IF(OR(P19="NR",P19="NA"),"NA", IF(P19<3,"Poor", IF(P19<3.8,"Average","High") ))) -> High | S19: =IFERROR( _xlfn.XLOOKUP(Q19,[2]Result!$A$7:$A$15,[2]Result!$C$7:$C$15,"Out of range",-1),"N/A") -> 2C | T19: =IF($D19>DATE(2023,12,31),"NA",IF(J19="","NR",J19)) -> 3.85 | U19: {=IF(OR(J19="NA",J19="NR",ISBLANK(J19)),J19,IFERROR(INDEX([2]Result!$C$7:$C$15,MATCH(1,(J19>=[2]Result!$A$7:$A$15)*(J19<=[2]Result!$B$7:$B$15),0)), "NA"))} -> 3A | V19: =IF($D19>DATE(2024,12,31),"NA",IF(M19="","NR",M19)) -> 5 | W19: {=IF(OR(M19="NA",M19="NR",ISBLANK(M19)),M19,IFERROR(INDEX([2]Result!$C$7:$C$15,MATCH(1,(M19>=[2]Result!$A$7:$A$15)*(M19<=[2]Result!$B$7:$B$15),0)), "NA"))} -> 3C
A20: 9 | B20: 10115 | C20: ='[2]Evalution 25'!B10 -> Ahmed M M Omran | D20: 44119 | E20: ='[2]Evalution 25'!C10 -> Dubai | F20: ='[2]Evalution 25'!E10 -> Senior Traffic Manager | G20: ='[2]Evalution 25'!D10 -> Traffic | H20: ='[2]Evalutaion 23'!G8 -> 0 | I20: ='[2]Evalutaion 23'!H8 -> 3.8 | J20: =IF(COUNT(H20:I20)>0,AVERAGEIF(H20:I20,">=0"), IF(AND(ISNUMBER(D20),D20<=DATE(2023,12,31)),"NR","NA")) -> 1.9 | K20: ='[2]Evalutaion 24'!G8 -> 3.6 | L20: ='[2]Evalutaion 24'!H8 -> 4 | M20: =IF(COUNT(K20:L20)>0,AVERAGEIF(K20:L20,">=0"), IF(AND(ISNUMBER(D20),D20<=DATE(2024,12,31)),"NR","NA")) -> 3.8 | N20: ='[2]Evalution 25'!G10 -> 4.8 | O20: ='[2]Evalution 25'!H10 -> 4.7 | P20: =IF(COUNT(N20:O20)>0,AVERAGEIF(N20:O20,">=0"), IF(AND(ISNUMBER(D20),D20<=DATE(2025,12,31)),"NR","NA")) -> 4.75 | Q20: =AVERAGE(J20,M20,P20,) -> 2.6125 | R20: =IF(P20="","", IF(OR(P20="NR",P20="NA"),"NA", IF(P20<3,"Poor", IF(P20<3.8,"Average","High") ))) -> High | S20: =IFERROR( _xlfn.XLOOKUP(Q20,[2]Result!$A$7:$A$15,[2]Result!$C$7:$C$15,"Out of range",-1),"N/A") -> 2B | T20: =IF($D20>DATE(2023,12,31),"NA",IF(J20="","NR",J20)) -> 1.9 | U20: {=IF(OR(J20="NA",J20="NR",ISBLANK(J20)),J20,IFERROR(INDEX([2]Result!$C$7:$C$15,MATCH(1,(J20>=[2]Result!$A$7:$A$15)*(J20<=[2]Result!$B$7:$B$15),0)), "NA"))} -> 1C | V20: =IF($D20>DATE(2024,12,31),"NA",IF(M20="","NR",M20)) -> 3.8 | W20: {=IF(OR(M20="NA",M20="NR",ISBLANK(M20)),M20,IFERROR(INDEX([2]Result!$C$7:$C$15,MATCH(1,(M20>=[2]Result!$A$7:$A$15)*(M20<=[2]Result!$B$7:$B$15),0)), "NA"))} -> 3A
A21: 10 | B21: 48322 | C21: ='[2]Evalution 25'!B11 -> Ahmed abdelhady abdelhady mohamed Elshorbagy | D21: 45261 | E21: ='[2]Evalution 25'!C11 -> Cairo | F21: ='[2]Evalution 25'!E11 -> Sales Supervisor | G21: ='[2]Evalution 25'!D11 -> Agency Partnerships | H21: - | I21: - | J21: =IF(COUNT(H21:I21)>0,AVERAGEIF(H21:I21,">=0"), IF(AND(ISNUMBER(D21),D21<=DATE(2023,12,31)),"NR","NA")) -> NR | K21: ='[2]Evalutaion 24'!G9 -> 4 | L21: ='[2]Evalutaion 24'!H9 -> 3.7 | M21: =IF(COUNT(K21:L21)>0,AVERAGEIF(K21:L21,">=0"), IF(AND(ISNUMBER(D21),D21<=DATE(2024,12,31)),"NR","NA")) -> 3.85 | N21: ='[2]Evalution 25'!G11 -> 3.5 | O21: ='[2]Evalution 25'!H11 -> 4 | P21: =IF(COUNT(N21:O21)>0,AVERAGEIF(N21:O21,">=0"), IF(AND(ISNUMBER(D21),D21<=DATE(2025,12,31)),"NR","NA")) -> 3.75 | Q21: =AVERAGE(J21,M21,P21,) -> 2.5333333 | R21: =IF(P21="","", IF(OR(P21="NR",P21="NA"),"NA", IF(P21<3,"Poor", IF(P21<3.8,"Average","High") ))) -> Average | S21: =IFERROR( _xlfn.XLOOKUP(Q21,[2]Result!$A$7:$A$15,[2]Result!$C$7:$C$15,"Out of range",-1),"N/A") -> 2A | T21: =IF($D21>DATE(2023,12,31),"NA",IF(J21="","NR",J21)) -> NR | U21: {=IF(OR(J21="NA",J21="NR",ISBLANK(J21)),J21,IFERROR(INDEX([2]Result!$C$7:$C$15,MATCH(1,(J21>=[2]Result!$A$7:$A$15)*(J21<=[2]Result!$B$7:$B$15),0)), "NA"))} -> NR | V21: =IF($D21>DATE(2024,12,31),"NA",IF(M21="","NR",M21)) -> 3.85 | W21: {=IF(OR(M21="NA",M21="NR",ISBLANK(M21)),M21,IFERROR(INDEX([2]Result!$C$7:$C$15,MATCH(1,(M21>=[2]Result!$A$7:$A$15)*(M21<=[2]Result!$B$7:$B$15),0)), "NA"))} -> 3A
A22: 11 | B22: 6572 | C22: ='[2]Evalution 25'!B12 -> Jyoti Kanda | D22: 44293 | E22: ='[2]Evalution 25'!C12 -> Dubai | F22: ='[2]Evalution 25'!E12 -> Director of Commercial Finance | G22: ='[2]Evalution 25'!D12 -> Finance | H22: ='[2]Evalutaion 23'!G9 -> 3.5 | I22: ='[2]Evalutaion 23'!H9 -> 3.3 | J22: =IF(COUNT(H22:I22)>0,AVERAGEIF(H22:I22,">=0"), IF(AND(ISNUMBER(D22),D22<=DATE(2023,12,31)),"NR","NA")) -> 3.4 | K22: ='[2]Evalutaion 24'!G10 -> 3.5 | L22: ='[2]Evalutaion 24'!H10 -> 3.5 | M22: =IF(COUNT(K22:L22)>0,AVERAGEIF(K22:L22,">=0"), IF(AND(ISNUMBER(D22),D22<=DATE(2024,12,31)),"NR","NA")) -> 3.5 | N22: ='[2]Evalution 25'!G12 -> 4.7 | O22: ='[2]Evalution 25'!H12 -> 4.7 | P22: =IF(COUNT(N22:O22)>0,AVERAGEIF(N22:O22,">=0"), IF(AND(ISNUMBER(D22),D22<=DATE(2025,12,31)),"NR","NA")) -> 4.7 | Q22: =AVERAGE(J22,M22,P22,) -> 2.9 | R22: =IF(P22="","", IF(OR(P22="NR",P22="NA"),"NA", IF(P22<3,"Poor", IF(P22<3.8,"Average","High") ))) -> High | S22: =IFERROR( _xlfn.XLOOKUP(Q22,[2]Result!$A$7:$A$15,[2]Result!$C$7:$C$15,"Out of range",-1),"N/A") -> 2B | T22: =IF($D22>DATE(2023,12,31),"NA",IF(J22="","NR",J22)) -> 3.4 | U22: {=IF(OR(J22="NA",J22="NR",ISBLANK(J22)),J22,IFERROR(INDEX([2]Result!$C$7:$C$15,MATCH(1,(J22>=[2]Result!$A$7:$A$15)*(J22<=[2]Result!$B$7:$B$15),0)), "NA"))} -> 2C | V22: =IF($D22>DATE(2024,12,31),"NA",IF(M22="","NR",M22)) -> 3.5 | W22: {=IF(OR(M22="NA",M22="NR",ISBLANK(M22)),M22,IFERROR(INDEX([2]Result!$C$7:$C$15,MATCH(1,(M22>=[2]Result!$A$7:$A$15)*(M22<=[2]Result!$B$7:$B$15),0)), "NA"))} -> 2C
A23: 12 | B23: 6609 | C23: ='[2]Evalution 25'!B13 -> Ahmed Hamed Ibrahim kamel | D23: 44470 | E23: ='[2]Evalution 25'!C13 -> Cairo | F23: ='[2]Evalution 25'!E13 -> Sales Director | G23: ='[2]Evalution 25'!D13 -> Agency Partnerships | H23: ='[2]Evalutaion 23'!G10 -> 3.7 | I23: ='[2]Evalutaion 23'!H10 -> 3.8 | J23: =IF(COUNT(H23:I23)>0,AVERAGEIF(H23:I23,">=0"), IF(AND(ISNUMBER(D23),D23<=DATE(2023,12,31)),"NR","NA")) -> 3.75 | K23: ='[2]Evalutaion 24'!G11 -> 4.3 | L23: ='[2]Evalutaion 24'!H11 -> 3.7 | M23: =IF(COUNT(K23:L23)>0,AVERAGEIF(K23:L23,">=0"), IF(AND(ISNUMBER(D23),D23<=DATE(2024,12,31)),"NR","NA")) -> 4 | N23: ='[2]Evalution 25'!G13 -> 4.5 | O23: ='[2]Evalution 25'!H13 -> 3.7 | P23: =IF(COUNT(N23:O23)>0,AVERAGEIF(N23:O23,">=0"), IF(AND(ISNUMBER(D23),D23<=DATE(2025,12,31)),"NR","NA")) -> 4.1 | Q23: =AVERAGE(J23,M23,P23,) -> 2.9625 | R23: =IF(P23="","", IF(OR(P23="NR",P23="NA"),"NA", IF(P23<3,"Poor", IF(P23<3.8,"Average","High") ))) -> High | S23: =IFERROR( _xlfn.XLOOKUP(Q23,[2]Result!$A$7:$A$15,[2]Result!$C$7:$C$15,"Out of range",-1),"N/A") -> 2B | T23: =IF($D23>DATE(2023,12,31),"NA",IF(J23="","NR",J23)) -> 3.75 | U23: {=IF(OR(J23="NA",J23="NR",ISBLANK(J23)),J23,IFERROR(INDEX([2]Result!$C$7:$C$15,MATCH(1,(J23>=[2]Result!$A$7:$A$15)*(J23<=[2]Result!$B$7:$B$15),0)), "NA"))} -> 3A | V23: =IF($D23>DATE(2024,12,31),"NA",IF(M23="","NR",M23)) -> 4 | W23: {=IF(OR(M23="NA",M23="NR",ISBLANK(M23)),M23,IFERROR(INDEX([2]Result!$C$7:$C$15,MATCH(1,(M23>=[2]Result!$A$7:$A$15)*(M23<=[2]Result!$B$7:$B$15),0)), "NA"))} -> 3A
A24: 13 | B24: 50733 | C24: ='[2]Evalution 25'!B14 -> Minhal Ali | D24: 45866 | E24: ='[2]Evalution 25'!C14 -> Dubai | F24: ='[2]Evalution 25'!E14 -> Finance Supervisor-MMS | G24: ='[2]Evalution 25'!D14 -> Finance | H24: - | I24: - | J24: =IF(COUNT(H24:I24)>0,AVERAGEIF(H24:I24,">=0"), IF(AND(ISNUMBER(D24),D24<=DATE(2023,12,31)),"NR","NA")) -> NA | K24: - | L24: - | M24: =IF(COUNT(K24:L24)>0,AVERAGEIF(K24:L24,">=0"), IF(AND(ISNUMBER(D24),D24<=DATE(2024,12,31)),"NR","NA")) -> NA | N24: ='[2]Evalution 25'!G14 -> 4.4 | O24: ='[2]Evalution 25'!H14 -> 5 | P24: =IF(COUNT(N24:O24)>0,AVERAGEIF(N24:O24,">=0"), IF(AND(ISNUMBER(D24),D24<=DATE(2025,12,31)),"NR","NA")) -> 4.7 | Q24: =AVERAGE(J24,M24,P24,) -> 2.35 | R24: =IF(P24="","", IF(OR(P24="NR",P24="NA"),"NA", IF(P24<3,"Poor", IF(P24<3.8,"Average","High") ))) -> High | S24: =IFERROR( _xlfn.XLOOKUP(Q24,[2]Result!$A$7:$A$15,[2]Result!$C$7:$C$15,"Out of range",-1),"N/A") -> 2A | T24: =IF($D24>DATE(2023,12,31),"NA",IF(J24="","NR",J24)) -> NA | U24: {=IF(OR(J24="NA",J24="NR",ISBLANK(J24)),J24,IFERROR(INDEX([2]Result!$C$7:$C$15,MATCH(1,(J24>=[2]Result!$A$7:$A$15)*(J24<=[2]Result!$B$7:$B$15),0)), "NA"))} -> NA | V24: =IF($D24>DATE(2024,12,31),"NA",IF(M24="","NR",M24)) -> NA | W24: {=IF(OR(M24="NA",M24="NR",ISBLANK(M24)),M24,IFERROR(INDEX([2]Result!$C$7:$C$15,MATCH(1,(M24>=[2]Result!$A$7:$A$15)*(M24<=[2]Result!$B$7:$B$15),0)), "NA"))} -> NA
A25: 14 | B25: 10853 | C25: ='[2]Evalution 25'!B15 -> Salem Khader Masood | D25: 44381 | E25: ='[2]Evalution 25'!C15 -> Dubai | F25: ='[2]Evalution 25'!E15 -> Senior Finance Manager-MMS | G25: ='[2]Evalution 25'!D15 -> Finance | H25: ='[2]Evalutaion 23'!G11 -> 3.5 | I25: ='[2]Evalutaion 23'!H11 -> 3 | J25: =IF(COUNT(H25:I25)>0,AVERAGEIF(H25:I25,">=0"), IF(AND(ISNUMBER(D25),D25<=DATE(2023,12,31)),"NR","NA")) -> 3.25 | K25: ='[2]Evalutaion 24'!G12 -> 4 | L25: ='[2]Evalutaion 24'!H12 -> 4 | M25: =IF(COUNT(K25:L25)>0,AVERAGEIF(K25:L25,">=0"), IF(AND(ISNUMBER(D25),D25<=DATE(2024,12,31)),"NR","NA")) -> 4 | N25: ='[2]Evalution 25'!G15 -> 4.6 | O25: ='[2]Evalution 25'!H15 -> 4.8 | P25: =IF(COUNT(N25:O25)>0,AVERAGEIF(N25:O25,">=0"), IF(AND(ISNUMBER(D25),D25<=DATE(2025,12,31)),"NR","NA")) -> 4.7 | Q25: =AVERAGE(J25,M25,P25,) -> 2.9875 | R25: =IF(P25="","", IF(OR(P25="NR",P25="NA"),"NA", IF(P25<3,"Poor", IF(P25<3.8,"Average","High") ))) -> High | S25: =IFERROR( _xlfn.XLOOKUP(Q25,[2]Result!$A$7:$A$15,[2]Result!$C$7:$C$15,"Out of range",-1),"N/A") -> 2B | T25: =IF($D25>DATE(2023,12,31),"NA",IF(J25="","NR",J25)) -> 3.25 | U25: {=IF(OR(J25="NA",J25="NR",ISBLANK(J25)),J25,IFERROR(INDEX([2]Result!$C$7:$C$15,MATCH(1,(J25>=[2]Result!$A$7:$A$15)*(J25<=[2]Result!$B$7:$B$15),0)), "NA"))} -> 2C | V25: =IF($D25>DATE(2024,12,31),"NA",IF(M25="","NR",M25)) -> 4 | W25: {=IF(OR(M25="NA",M25="NR",ISBLANK(M25)),M25,IFERROR(INDEX([2]Result!$C$7:$C$15,MATCH(1,(M25>=[2]Result!$A$7:$A$15)*(M25<=[2]Result!$B$7:$B$15),0)), "NA"))} -> 3A
A26: 15 | B26: 49223 | C26: ='[2]Evalution 25'!B16 -> Ahmed Mohammed Eldabbagh | D26: 45417 | E26: ='[2]Evalution 25'!C16 -> Riyadh | F26: ='[2]Evalution 25'!E16 -> Integrated Planning Senior Executive | G26: ='[2]Evalution 25'!D16 -> Research | H26: - | I26: - | J26: =IF(COUNT(H26:I26)>0,AVERAGEIF(H26:I26,">=0"), IF(AND(ISNUMBER(D26),D26<=DATE(2023,12,31)),"NR","NA")) -> NA | K26: ='[2]Evalutaion 24'!G13 -> 4.5 | L26: ='[2]Evalutaion 24'!H13 -> 4 | M26: =IF(COUNT(K26:L26)>0,AVERAGEIF(K26:L26,">=0"), IF(AND(ISNUMBER(D26),D26<=DATE(2024,12,31)),"NR","NA")) -> 4.25 | N26: ='[2]Evalution 25'!G16 -> 4 | O26: ='[2]Evalution 25'!H16 -> 4 | P26: =IF(COUNT(N26:O26)>0,AVERAGEIF(N26:O26,">=0"), IF(AND(ISNUMBER(D26),D26<=DATE(2025,12,31)),"NR","NA")) -> 4 | Q26: =AVERAGE(J26,M26,P26,) -> 2.75 | R26: =IF(P26="","", IF(OR(P26="NR",P26="NA"),"NA", IF(P26<3,"Poor", IF(P26<3.8,"Average","High") ))) -> High | S26: =IFERROR( _xlfn.XLOOKUP(Q26,[2]Result!$A$7:$A$15,[2]Result!$C$7:$C$15,"Out of range",-1),"N/A") -> 2B | T26: =IF($D26>DATE(2023,12,31),"NA",IF(J26="","NR",J26)) -> NA | U26: {=IF(OR(J26="NA",J26="NR",ISBLANK(J26)),J26,IFERROR(INDEX([2]Result!$C$7:$C$15,MATCH(1,(J26>=[2]Result!$A$7:$A$15)*(J26<=[2]Result!$B$7:$B$15),0)), "NA"))} -> NA | V26: =IF($D26>DATE(2024,12,31),"NA",IF(M26="","NR",M26)) -> 4.25 | W26: {=IF(OR(M26="NA",M26="NR",ISBLANK(M26)),M26,IFERROR(INDEX([2]Result!$C$7:$C$15,MATCH(1,(M26>=[2]Result!$A$7:$A$15)*(M26<=[2]Result!$B$7:$B$15),0)), "NA"))} -> 3B
A27: 16 | B27: 6570 | C27: ='[2]Evalution 25'!B17 -> Ahmed Mostafa Ghonemy Mostafa | D27: 44290 | E27: ='[2]Evalution 25'!C17 -> Cairo | F27: ='[2]Evalution 25'!E17 -> Traffic Supervisor | G27: ='[2]Evalution 25'!D17 -> Traffic | H27: ='[2]Evalutaion 23'!G12 -> 4 | I27: ='[2]Evalutaion 23'!H12 -> 3.7 | J27: =IF(COUNT(H27:I27)>0,AVERAGEIF(H27:I27,">=0"), IF(AND(ISNUMBER(D27),D27<=DATE(2023,12,31)),"NR","NA")) -> 3.85 | K27: ='[2]Evalutaion 24'!G14 -> 3.7 | L27: ='[2]Evalutaion 24'!H14 -> 3.8 | M27: =IF(COUNT(K27:L27)>0,AVERAGEIF(K27:L27,">=0"), IF(AND(ISNUMBER(D27),D27<=DATE(2024,12,31)),"NR","NA")) -> 3.75 | N27: ='[2]Evalution 25'!G17 -> 3.8 | O27: ='[2]Evalution 25'!H17 -> 4 | P27: =IF(COUNT(N27:O27)>0,AVERAGEIF(N27:O27,">=0"), IF(AND(ISNUMBER(D27),D27<=DATE(2025,12,31)),"NR","NA")) -> 3.9 | Q27: =AVERAGE(J27,M27,P27,) -> 2.875 | R27: =IF(P27="","", IF(OR(P27="NR",P27="NA"),"NA", IF(P27<3,"Poor", IF(P27<3.8,"Average","High") ))) -> High | S27: =IFERROR( _xlfn.XLOOKUP(Q27,[2]Result!$A$7:$A$15,[2]Result!$C$7:$C$15,"Out of range",-1),"N/A") -> 2B | T27: =IF($D27>DATE(2023,12,31),"NA",IF(J27="","NR",J27)) -> 3.85 | U27: {=IF(OR(J27="NA",J27="NR",ISBLANK(J27)),J27,IFERROR(INDEX([2]Result!$C$7:$C$15,MATCH(1,(J27>=[2]Result!$A$7:$A$15)*(J27<=[2]Result!$B$7:$B$15),0)), "NA"))} -> 3A | V27: =IF($D27>DATE(2024,12,31),"NA",IF(M27="","NR",M27)) -> 3.75 | W27: {=IF(OR(M27="NA",M27="NR",ISBLANK(M27)),M27,IFERROR(INDEX([2]Result!$C$7:$C$15,MATCH(1,(M27>=[2]Result!$A$7:$A$15)*(M27<=[2]Result!$B$7:$B$15),0)), "NA"))} -> 3A
A28: 17 | B28: 6555 | C28: ='[2]Evalution 25'!B18 -> Ahmed Tawfek Mahmoud Alasyouty | D28: 44220 | E28: ='[2]Evalution 25'!C18 -> Cairo | F28: ='[2]Evalution 25'!E18 -> Assistant Manager - Traffic | G28: ='[2]Evalution 25'!D18 -> Traffic | H28: ='[2]Evalutaion 23'!G13 -> 4.2 | I28: ='[2]Evalutaion 23'!H13 -> 4.5 | J28: =IF(COUNT(H28:I28)>0,AVERAGEIF(H28:I28,">=0"), IF(AND(ISNUMBER(D28),D28<=DATE(2023,12,31)),"NR","NA")) -> 4.35 | K28: ='[2]Evalutaion 24'!G15 -> 4.4 | L28: ='[2]Evalutaion 24'!H15 -> 4.3 | M28: =IF(COUNT(K28:L28)>0,AVERAGEIF(K28:L28,">=0"), IF(AND(ISNUMBER(D28),D28<=DATE(2024,12,31)),"NR","NA")) -> 4.35 | N28: ='[2]Evalution 25'!G18 -> 3.7 | O28: ='[2]Evalution 25'!H18 -> 3.8 | P28: =IF(COUNT(N28:O28)>0,AVERAGEIF(N28:O28,">=0"), IF(AND(ISNUMBER(D28),D28<=DATE(2025,12,31)),"NR","NA")) -> 3.75 | Q28: =AVERAGE(J28,M28,P28,) -> 3.1125 | R28: =IF(P28="","", IF(OR(P28="NR",P28="NA"),"NA", IF(P28<3,"Poor", IF(P28<3.8,"Average","High") ))) -> Average | S28: =IFERROR( _xlfn.XLOOKUP(Q28,[2]Result!$A$7:$A$15,[2]Result!$C$7:$C$15,"Out of range",-1),"N/A") -> 2C | T28: =IF($D28>DATE(2023,12,31),"NA",IF(J28="","NR",J28)) -> 4.35 | U28: {=IF(OR(J28="NA",J28="NR",ISBLANK(J28)),J28,IFERROR(INDEX([2]Result!$C$7:$C$15,MATCH(1,(J28>=[2]Result!$A$7:$A$15)*(J28<=[2]Result!$B$7:$B$15),0)), "NA"))} -> 3B | V28: =IF($D28>DATE(2024,12,31),"NA",IF(M28="","NR",M28)) -> 4.35 | W28: {=IF(OR(M28="NA",M28="NR",ISBLANK(M28)),M28,IFERROR(INDEX([2]Result!$C$7:$C$15,MATCH(1,(M28>=[2]Result!$A$7:$A$15)*(M28<=[2]Result!$B$7:$B$15),0)), "NA"))} -> 3B
A29: 18 | B29: 6595 | C29: ='[2]Evalution 25'!B19 -> Al Shaimaa Mohamed Mohamed Sadek Alshoura | D29: 44381 | E29: ='[2]Evalution 25'!C19 -> Cairo | F29: ='[2]Evalution 25'!E19 -> HR Manager | G29: ='[2]Evalution 25'!D19 -> HR | H29: ='[2]Evalutaion 23'!G14 -> 5 | I29: ='[2]Evalutaion 23'!H14 -> 4.8 | J29: =IF(COUNT(H29:I29)>0,AVERAGEIF(H29:I29,">=0"), IF(AND(ISNUMBER(D29),D29<=DATE(2023,12,31)),"NR","NA")) -> 4.9 | K29: ='[2]Evalutaion 24'!G16 -> 4.7 | L29: ='[2]Evalutaion 24'!H16 -> 5 | M29: =IF(COUNT(K29:L29)>0,AVERAGEIF(K29:L29,">=0"), IF(AND(ISNUMBER(D29),D29<=DATE(2024,12,31)),"NR","NA")) -> 4.85 | N29: ='[2]Evalution 25'!G19 -> 4.6 | O29: ='[2]Evalution 25'!H19 -> 5 | P29: =IF(COUNT(N29:O29)>0,AVERAGEIF(N29:O29,">=0"), IF(AND(ISNUMBER(D29),D29<=DATE(2025,12,31)),"NR","NA")) -> 4.8 | Q29: =AVERAGE(J29,M29,P29,) -> 3.6375 | R29: =IF(P29="","", IF(OR(P29="NR",P29="NA"),"NA", IF(P29<3,"Poor", IF(P29<3.8,"Average","High") ))) -> High | S29: =IFERROR( _xlfn.XLOOKUP(Q29,[2]Result!$A$7:$A$15,[2]Result!$C$7:$C$15,"Out of range",-1),"N/A") -> 3A | T29: =IF($D29>DATE(2023,12,31),"NA",IF(J29="","NR",J29)) -> 4.9 | U29: {=IF(OR(J29="NA",J29="NR",ISBLANK(J29)),J29,IFERROR(INDEX([2]Result!$C$7:$C$15,MATCH(1,(J29>=[2]Result!$A$7:$A$15)*(J29<=[2]Result!$B$7:$B$15),0)), "NA"))} -> 3C | V29: =IF($D29>DATE(2024,12,31),"NA",IF(M29="","NR",M29)) -> 4.85 | W29: {=IF(OR(M29="NA",M29="NR",ISBLANK(M29)),M29,IFERROR(INDEX([2]Result!$C$7:$C$15,MATCH(1,(M29>=[2]Result!$A$7:$A$15)*(M29<=[2]Result!$B$7:$B$15),0)), "NA"))} -> 3C
A30: 19 | B30: 49926 | C30: ='[2]Evalution 25'!B20 -> Alaa Mohamed Ahmed Aboelenin Zaghloul | D30: 45597 | E30: ='[2]Evalution 25'!C20 -> Cairo | F30: ='[2]Evalution 25'!E20 -> Client Service Executive | G30: ='[2]Evalution 25'!D20 -> Agency Partnerships | H30: - | I30: - | J30: =IF(COUNT(H30:I30)>0,AVERAGEIF(H30:I30,">=0"), IF(AND(ISNUMBER(D30),D30<=DATE(2023,12,31)),"NR","NA")) -> NA | K30: - | L30: - | M30: =IF(COUNT(K30:L30)>0,AVERAGEIF(K30:L30,">=0"), IF(AND(ISNUMBER(D30),D30<=DATE(2024,12,31)),"NR","NA")) -> NR | N30: ='[2]Evalution 25'!G20 -> 3 | O30: ='[2]Evalution 25'!H20 -> 3.3 | P30: =IF(COUNT(N30:O30)>0,AVERAGEIF(N30:O30,">=0"), IF(AND(ISNUMBER(D30),D30<=DATE(2025,12,31)),"NR","NA")) -> 3.15 | Q30: =AVERAGE(J30,M30,P30,) -> 1.575 | R30: =IF(P30="","", IF(OR(P30="NR",P30="NA"),"NA", IF(P30<3,"Poor", IF(P30<3.8,"Average","High") ))) -> Average | S30: =IFERROR( _xlfn.XLOOKUP(Q30,[2]Result!$A$7:$A$15,[2]Result!$C$7:$C$15,"Out of range",-1),"N/A") -> 1B | T30: =IF($D30>DATE(2023,12,31),"NA",IF(J30="","NR",J30)) -> NA | U30: {=IF(OR(J30="NA",J30="NR",ISBLANK(J30)),J30,IFERROR(INDEX([2]Result!$C$7:$C$15,MATCH(1,(J30>=[2]Result!$A$7:$A$15)*(J30<=[2]Result!$B$7:$B$15),0)), "NA"))} -> NA | V30: =IF($D30>DATE(2024,12,31),"NA",IF(M30="","NR",M30)) -> NR | W30: {=IF(OR(M30="NA",M30="NR",ISBLANK(M30)),M30,IFERROR(INDEX([2]Result!$C$7:$C$15,MATCH(1,(M30>=[2]Result!$A$7:$A$15)*(M30<=[2]Result!$B$7:$B$15),0)), "NA"))} -> NR
A31: 20 | B31: 50433 | C31: ='[2]Evalution 25'!B21 -> Alaa Mohamed Aly | D31: 45781 | E31: ='[2]Evalution 25'!C21 -> Cairo | F31: ='[2]Evalution 25'!E21 -> Office Manager | G31: ='[2]Evalution 25'!D21 -> Admin | H31: - | I31: - | J31: =IF(COUNT(H31:I31)>0,AVERAGEIF(H31:I31,">=0"), IF(AND(ISNUMBER(D31),D31<=DATE(2023,12,31)),"NR","NA")) -> NA | K31: - | L31: - | M31: =IF(COUNT(K31:L31)>0,AVERAGEIF(K31:L31,">=0"), IF(AND(ISNUMBER(D31),D31<=DATE(2024,12,31)),"NR","NA")) -> NA | N31: ='[2]Evalution 25'!G21 -> 3.6 | O31: ='[2]Evalution 25'!H21 -> 3.7 | P31: =IF(COUNT(N31:O31)>0,AVERAGEIF(N31:O31,">=0"), IF(AND(ISNUMBER(D31),D31<=DATE(2025,12,31)),"NR","NA")) -> 3.65 | Q31: =AVERAGE(J31,M31,P31,) -> 1.825 | R31: =IF(P31="","", IF(OR(P31="NR",P31="NA"),"NA", IF(P31<3,"Poor", IF(P31<3.8,"Average","High") ))) -> Average | S31: =IFERROR( _xlfn.XLOOKUP(Q31,[2]Result!$A$7:$A$15,[2]Result!$C$7:$C$15,"Out of range",-1),"N/A") -> 1C | T31: =IF($D31>DATE(2023,12,31),"NA",IF(J31="","NR",J31)) -> NA | U31: {=IF(OR(J31="NA",J31="NR",ISBLANK(J31)),J31,IFERROR(INDEX([2]Result!$C$7:$C$15,MATCH(1,(J31>=[2]Result!$A$7:$A$15)*(J31<=[2]Result!$B$7:$B$15),0)), "NA"))} -> NA | V31: =IF($D31>DATE(2024,12,31),"NA",IF(M31="","NR",M31)) -> NA | W31: {=IF(OR(M31="NA",M31="NR",ISBLANK(M31)),M31,IFERROR(INDEX([2]Result!$C$7:$C$15,MATCH(1,(M31>=[2]Result!$A$7:$A$15)*(M31<=[2]Result!$B$7:$B$15),0)), "NA"))} -> NA
A32: 21 | B32: 49579 | C32: ='[2]Evalution 25'!B22 -> Alaaeldin Eid ahmed Fadl | D32: 45522 | E32: ='[2]Evalution 25'!C22 -> Cairo | F32: ='[2]Evalution 25'!E22 -> Office Boy | G32: ='[2]Evalution 25'!D22 -> Admin | H32: - | I32: - | J32: =IF(COUNT(H32:I32)>0,AVERAGEIF(H32:I32,">=0"), IF(AND(ISNUMBER(D32),D32<=DATE(2023,12,31)),"NR","NA")) -> NA | K32: - | L32: - | M32: =IF(COUNT(K32:L32)>0,AVERAGEIF(K32:L32,">=0"), IF(AND(ISNUMBER(D32),D32<=DATE(2024,12,31)),"NR","NA")) -> NR | N32: ='[2]Evalution 25'!G22 -> 3.5 | O32: ='[2]Evalution 25'!H22 -> 3.2 | P32: =IF(COUNT(N32:O32)>0,AVERAGEIF(N32:O32,">=0"), IF(AND(ISNUMBER(D32),D32<=DATE(2025,12,31)),"NR","NA")) -> 3.35 | Q32: =AVERAGE(J32,M32,P32,) -> 1.675 | R32: =IF(P32="","", IF(OR(P32="NR",P32="NA"),"NA", IF(P32<3,"Poor", IF(P32<3.8,"Average","High") ))) -> Average | S32: =IFERROR( _xlfn.XLOOKUP(Q32,[2]Result!$A$7:$A$15,[2]Result!$C$7:$C$15,"Out of range",-1),"N/A") -> 1C | T32: =IF($D32>DATE(2023,12,31),"NA",IF(J32="","NR",J32)) -> NA | U32: {=IF(OR(J32="NA",J32="NR",ISBLANK(J32)),J32,IFERROR(INDEX([2]Result!$C$7:$C$15,MATCH(1,(J32>=[2]Result!$A$7:$A$15)*(J32<=[2]Result!$B$7:$B$15),0)), "NA"))} -> NA | V32: =IF($D32>DATE(2024,12,31),"NA",IF(M32="","NR",M32)) -> NR | W32: {=IF(OR(M32="NA",M32="NR",ISBLANK(M32)),M32,IFERROR(INDEX([2]Result!$C$7:$C$15,MATCH(1,(M32>=[2]Result!$A$7:$A$15)*(M32<=[2]Result!$B$7:$B$15),0)), "NA"))} -> NR
A33: 22 | B33: 31428 | C33: ='[2]Evalution 25'!B23 -> Alanoud Waleed Muhammed Almadi | D33: 44584 | E33: ='[2]Evalution 25'!C23 -> Riyadh | F33: ='[2]Evalution 25'!E23 -> Client Growth Senior Executive | G33: ='[2]Evalution 25'!D23 -> Client Growth | H33: ='[2]Evalutaion 23'!G15 -> 4.4 | I33: ='[2]Evalutaion 23'!H15 -> 4.7 | J33: =IF(COUNT(H33:I33)>0,AVERAGEIF(H33:I33,">=0"), IF(AND(ISNUMBER(D33),D33<=DATE(2023,12,31)),"NR","NA")) -> 4.55 | K33: ='[2]Evalutaion 24'!G18 -> 3.1 | L33: ='[2]Evalutaion 24'!H18 -> 3.7 | M33: =IF(COUNT(K33:L33)>0,AVERAGEIF(K33:L33,">=0"), IF(AND(ISNUMBER(D33),D33<=DATE(2024,12,31)),"NR","NA")) -> 3.4 | N33: ='[2]Evalution 25'!G23 -> 4.7 | O33: ='[2]Evalution 25'!H23 -> 4.8 | P33: =IF(COUNT(N33:O33)>0,AVERAGEIF(N33:O33,">=0"), IF(AND(ISNUMBER(D33),D33<=DATE(2025,12,31)),"NR","NA")) -> 4.75 | Q33: =AVERAGE(J33,M33,P33,) -> 3.175 | R33: =IF(P33="","", IF(OR(P33="NR",P33="NA"),"NA", IF(P33<3,"Poor", IF(P33<3.8,"Average","High") ))) -> High | S33: =IFERROR( _xlfn.XLOOKUP(Q33,[2]Result!$A$7:$A$15,[2]Result!$C$7:$C$15,"Out of range",-1),"N/A") -> 2C | T33: =IF($D33>DATE(2023,12,31),"NA",IF(J33="","NR",J33)) -> 4.55 | U33: {=IF(OR(J33="NA",J33="NR",ISBLANK(J33)),J33,IFERROR(INDEX([2]Result!$C$7:$C$15,MATCH(1,(J33>=[2]Result!$A$7:$A$15)*(J33<=[2]Result!$B$7:$B$15),0)), "NA"))} -> NA | V33: =IF($D33>DATE(2024,12,31),"NA",IF(M33="","NR",M33)) -> 3.4 | W33: {=IF(OR(M33="NA",M33="NR",ISBLANK(M33)),M33,IFERROR(INDEX([2]Result!$C$7:$C$15,MATCH(1,(M33>=[2]Result!$A$7:$A$15)*(M33<=[2]Result!$B$7:$B$15),0)), "NA"))} -> 2C
A34: 23 | B34: 47437 | C34: ='[2]Evalution 25'!B24 -> Ali Imad Younes | D34: 45012 | E34: ='[2]Evalution 25'!C24 -> Dubai | F34: ='[2]Evalution 25'!E24 -> Content Solutions Senior Executive | G34: ='[2]Evalution 25'!D24 -> Content Solutions | H34: ='[2]Evalutaion 23'!G16 -> 3.5 | I34: ='[2]Evalutaion 23'!H16 -> 3.5 | J34: =IF(COUNT(H34:I34)>0,AVERAGEIF(H34:I34,">=0"), IF(AND(ISNUMBER(D34),D34<=DATE(2023,12,31)),"NR","NA")) -> 3.5 | K34: ='[2]Evalutaion 24'!G19 -> 3.8 | L34: ='[2]Evalutaion 24'!H19 -> 3.7 | M34: =IF(COUNT(K34:L34)>0,AVERAGEIF(K34:L34,">=0"), IF(AND(ISNUMBER(D34),D34<=DATE(2024,12,31)),"NR","NA")) -> 3.75 | N34: ='[2]Evalution 25'!G24 -> 4.8 | O34: ='[2]Evalution 25'!H24 -> 4.3 | P34: =IF(COUNT(N34:O34)>0,AVERAGEIF(N34:O34,">=0"), IF(AND(ISNUMBER(D34),D34<=DATE(2025,12,31)),"NR","NA")) -> 4.55 | Q34: =AVERAGE(J34,M34,P34,) -> 2.95 | R34: =IF(P34="","", IF(OR(P34="NR",P34="NA"),"NA", IF(P34<3,"Poor", IF(P34<3.8,"Average","High") ))) -> High | S34: =IFERROR( _xlfn.XLOOKUP(Q34,[2]Result!$A$7:$A$15,[2]Result!$C$7:$C$15,"Out of range",-1),"N/A") -> 2B | T34: =IF($D34>DATE(2023,12,31),"NA",IF(J34="","NR",J34)) -> 3.5 | U34: {=IF(OR(J34="NA",J34="NR",ISBLANK(J34)),J34,IFERROR(INDEX([2]Result!$C$7:$C$15,MATCH(1,(J34>=[2]Result!$A$7:$A$15)*(J34<=[2]Result!$B$7:$B$15),0)), "NA"))} -> 2C | V34: =IF($D34>DATE(2024,12,31),"NA",IF(M34="","NR",M34)) -> 3.75 | W34: {=IF(OR(M34="NA",M34="NR",ISBLANK(M34)),M34,IFERROR(INDEX([2]Result!$C$7:$C$15,MATCH(1,(M34>=[2]Result!$A$7:$A$15)*(M34<=[2]Result!$B$7:$B$15),0)), "NA"))} -> 3A
A35: 24 | B35: 48064 | C35: ='[2]Evalution 25'!B25 -> Ali Salam Ahmed Ahmed | D35: 45173 | E35: ='[2]Evalution 25'!C25 -> Dubai | F35: ='[2]Evalution 25'!E25 -> Client Growth Lead | G35: ='[2]Evalution 25'!D25 -> Client Growth | H35: ='[2]Evalutaion 23'!G17 -> 0 | I35: ='[2]Evalutaion 23'!H17 -> 3.3 | J35: =IF(COUNT(H35:I35)>0,AVERAGEIF(H35:I35,">=0"), IF(AND(ISNUMBER(D35),D35<=DATE(2023,12,31)),"NR","NA")) -> 1.65 | K35: ='[2]Evalutaion 24'!G20 -> 0 | L35: ='[2]Evalutaion 24'!H20 -> 0 | M35: =IF(COUNT(K35:L35)>0,AVERAGEIF(K35:L35,">=0"), IF(AND(ISNUMBER(D35),D35<=DATE(2024,12,31)),"NR","NA")) -> 0 | N35: ='[2]Evalution 25'!G25 -> 5 | O35: ='[2]Evalution 25'!H25 -> 5 | P35: =IF(COUNT(N35:O35)>0,AVERAGEIF(N35:O35,">=0"), IF(AND(ISNUMBER(D35),D35<=DATE(2025,12,31)),"NR","NA")) -> 5 | Q35: =AVERAGE(J35,M35,P35,) -> 1.6625 | R35: =IF(P35="","", IF(OR(P35="NR",P35="NA"),"NA", IF(P35<3,"Poor", IF(P35<3.8,"Average","High") ))) -> High | S35: =IFERROR( _xlfn.XLOOKUP(Q35,[2]Result!$A$7:$A$15,[2]Result!$C$7:$C$15,"Out of range",-1),"N/A") -> 1C | T35: =IF($D35>DATE(2023,12,31),"NA",IF(J35="","NR",J35)) -> 1.65 | U35: {=IF(OR(J35="NA",J35="NR",ISBLANK(J35)),J35,IFERROR(INDEX([2]Result!$C$7:$C$15,MATCH(1,(J35>=[2]Result!$A$7:$A$15)*(J35<=[2]Result!$B$7:$B$15),0)), "NA"))} -> 1C | V35: =IF($D35>DATE(2024,12,31),"NA",IF(M35="","NR",M35)) -> 0 | W35: {=IF(OR(M35="NA",M35="NR",ISBLANK(M35)),M35,IFERROR(INDEX([2]Result!$C$7:$C$15,MATCH(1,(M35>=[2]Result!$A$7:$A$15)*(M35<=[2]Result!$B$7:$B$15),0)), "NA"))} -> 1A
A36: 25 | B36: 6571 | C36: ='[2]Evalution 25'!B26 -> Alsayed Abo Bakr Abdelhay Abdullah | D36: 44290 | E36: ='[2]Evalution 25'!C26 -> Cairo | F36: ='[2]Evalution 25'!E26 -> Traffic Supervisor | G36: ='[2]Evalution 25'!D26 -> Traffic | H36: ='[2]Evalutaion 23'!G18 -> 4 | I36: ='[2]Evalutaion 23'!H18 -> 4 | J36: =IF(COUNT(H36:I36)>0,AVERAGEIF(H36:I36,">=0"), IF(AND(ISNUMBER(D36),D36<=DATE(2023,12,31)),"NR","NA")) -> 4 | K36: ='[2]Evalutaion 24'!G21 -> 3.6 | L36: ='[2]Evalutaion 24'!H21 -> 3.5 | M36: =IF(COUNT(K36:L36)>0,AVERAGEIF(K36:L36,">=0"), IF(AND(ISNUMBER(D36),D36<=DATE(2024,12,31)),"NR","NA")) -> 3.55 | N36: ='[2]Evalution 25'!G26 -> 3.7 | O36: ='[2]Evalution 25'!H26 -> 4 | P36: =IF(COUNT(N36:O36)>0,AVERAGEIF(N36:O36,">=0"), IF(AND(ISNUMBER(D36),D36<=DATE(2025,12,31)),"NR","NA")) -> 3.85 | Q36: =AVERAGE(J36,M36,P36,) -> 2.85 | R36: =IF(P36="","", IF(OR(P36="NR",P36="NA"),"NA", IF(P36<3,"Poor", IF(P36<3.8,"Average","High") ))) -> High | S36: =IFERROR( _xlfn.XLOOKUP(Q36,[2]Result!$A$7:$A$15,[2]Result!$C$7:$C$15,"Out of range",-1),"N/A") -> 2B | T36: =IF($D36>DATE(2023,12,31),"NA",IF(J36="","NR",J36)) -> 4 | U36: {=IF(OR(J36="NA",J36="NR",ISBLANK(J36)),J36,IFERROR(INDEX([2]Result!$C$7:$C$15,MATCH(1,(J36>=[2]Result!$A$7:$A$15)*(J36<=[2]Result!$B$7:$B$15),0)), "NA"))} -> 3A | V36: =IF($D36>DATE(2024,12,31),"NA",IF(M36="","NR",M36)) -> 3.55 | W36: {=IF(OR(M36="NA",M36="NR",ISBLANK(M36)),M36,IFERROR(INDEX([2]Result!$C$7:$C$15,MATCH(1,(M36>=[2]Result!$A$7:$A$15)*(M36<=[2]Result!$B$7:$B$15),0)), "NA"))} -> NA
A37: 26 | B37: 6552 | C37: ='[2]Evalution 25'!B27 -> Amira Mohamed Ali Soliman Soltan | D37: 44197 | E37: ='[2]Evalution 25'!C27 -> Cairo | F37: ='[2]Evalution 25'!E27 -> Sales Manager | G37: ='[2]Evalution 25'!D27 -> Agency Partnerships | H37: ='[2]Evalutaion 23'!G19 -> 4.7 | I37: ='[2]Evalutaion 23'!H19 -> 4.3 | J37: =IF(COUNT(H37:I37)>0,AVERAGEIF(H37:I37,">=0"), IF(AND(ISNUMBER(D37),D37<=DATE(2023,12,31)),"NR","NA")) -> 4.5 | K37: ='[2]Evalutaion 24'!G22 -> 4.3 | L37: ='[2]Evalutaion 24'!H22 -> 4 | M37: =IF(COUNT(K37:L37)>0,AVERAGEIF(K37:L37,">=0"), IF(AND(ISNUMBER(D37),D37<=DATE(2024,12,31)),"NR","NA")) -> 4.15 | N37: ='[2]Evalution 25'!G27 -> 4 | O37: ='[2]Evalution 25'!H27 -> 4 | P37: =IF(COUNT(N37:O37)>0,AVERAGEIF(N37:O37,">=0"), IF(AND(ISNUMBER(D37),D37<=DATE(2025,12,31)),"NR","NA")) -> 4 | Q37: =AVERAGE(J37,M37,P37,) -> 3.1625 | R37: =IF(P37="","", IF(OR(P37="NR",P37="NA"),"NA", IF(P37<3,"Poor", IF(P37<3.8,"Average","High") ))) -> High | S37: =IFERROR( _xlfn.XLOOKUP(Q37,[2]Result!$A$7:$A$15,[2]Result!$C$7:$C$15,"Out of range",-1),"N/A") -> 2C | T37: =IF($D37>DATE(2023,12,31),"NA",IF(J37="","NR",J37)) -> 4.5 | U37: {=IF(OR(J37="NA",J37="NR",ISBLANK(J37)),J37,IFERROR(INDEX([2]Result!$C$7:$C$15,MATCH(1,(J37>=[2]Result!$A$7:$A$15)*(J37<=[2]Result!$B$7:$B$15),0)), "NA"))} -> 3B | V37: =IF($D37>DATE(2024,12,31),"NA",IF(M37="","NR",M37)) -> 4.15 | W37: {=IF(OR(M37="NA",M37="NR",ISBLANK(M37)),M37,IFERROR(INDEX([2]Result!$C$7:$C$15,MATCH(1,(M37>=[2]Result!$A$7:$A$15)*(M37<=[2]Result!$B$7:$B$15),0)), "NA"))} -> 3B
A38: 27 | B38: 31257 | C38: ='[2]Evalution 25'!B28 -> Ammar Sami Hassan Subki | D38: 44501 | E38: ='[2]Evalution 25'!C28 -> Riyadh | F38: ='[2]Evalution 25'!E28 -> Head of HR and Admin Services | G38: ='[2]Evalution 25'!D28 -> HR | H38: ='[2]Evalutaion 23'!G20 -> 4 | I38: ='[2]Evalutaion 23'!H20 -> 3.8 | J38: =IF(COUNT(H38:I38)>0,AVERAGEIF(H38:I38,">=0"), IF(AND(ISNUMBER(D38),D38<=DATE(2023,12,31)),"NR","NA")) -> 3.9 | K38: ='[2]Evalutaion 24'!G23 -> 4.7 | L38: ='[2]Evalutaion 24'!H23 -> 4.5 | M38: =IF(COUNT(K38:L38)>0,AVERAGEIF(K38:L38,">=0"), IF(AND(ISNUMBER(D38),D38<=DATE(2024,12,31)),"NR","NA")) -> 4.6 | N38: ='[2]Evalution 25'!G28 -> 4.7 | O38: ='[2]Evalution 25'!H28 -> 4.8 | P38: =IF(COUNT(N38:O38)>0,AVERAGEIF(N38:O38,">=0"), IF(AND(ISNUMBER(D38),D38<=DATE(2025,12,31)),"NR","NA")) -> 4.75 | Q38: =AVERAGE(J38,M38,P38,) -> 3.3125 | R38: =IF(P38="","", IF(OR(P38="NR",P38="NA"),"NA", IF(P38<3,"Poor", IF(P38<3.8,"Average","High") ))) -> High | S38: =IFERROR( _xlfn.XLOOKUP(Q38,[2]Result!$A$7:$A$15,[2]Result!$C$7:$C$15,"Out of range",-1),"N/A") -> 2C | T38: =IF($D38>DATE(2023,12,31),"NA",IF(J38="","NR",J38)) -> 3.9 | U38: {=IF(OR(J38="NA",J38="NR",ISBLANK(J38)),J38,IFERROR(INDEX([2]Result!$C$7:$C$15,MATCH(1,(J38>=[2]Result!$A$7:$A$15)*(J38<=[2]Result!$B$7:$B$15),0)), "NA"))} -> 3A | V38: =IF($D38>DATE(2024,12,31),"NA",IF(M38="","NR",M38)) -> 4.6 | W38: {=IF(OR(M38="NA",M38="NR",ISBLANK(M38)),M38,IFERROR(INDEX([2]Result!$C$7:$C$15,MATCH(1,(M38>=[2]Result!$A$7:$A$15)*(M38<=[2]Result!$B$7:$B$15),0)), "NA"))} -> 3C
A39: 28 | B39: 6614 | C39: ='[2]Evalution 25'!B29 -> Amr Reda Amer Ghoniem | D39: 44501 | E39: ='[2]Evalution 25'!C29 -> Cairo | F39: ='[2]Evalution 25'!E29 -> Office Boy | G39: ='[2]Evalution 25'!D29 -> Admin | H39: ='[2]Evalutaion 23'!G21 -> 3 | I39: ='[2]Evalutaion 23'!H21 -> 3 | J39: =IF(COUNT(H39:I39)>0,AVERAGEIF(H39:I39,">=0"), IF(AND(ISNUMBER(D39),D39<=DATE(2023,12,31)),"NR","NA")) -> 3 | K39: ='[2]Evalutaion 24'!G24 -> 3 | L39: ='[2]Evalutaion 24'!H24 -> 3 | M39: =IF(COUNT(K39:L39)>0,AVERAGEIF(K39:L39,">=0"), IF(AND(ISNUMBER(D39),D39<=DATE(2024,12,31)),"NR","NA")) -> 3 | N39: ='[2]Evalution 25'!G29 -> 3 | O39: ='[2]Evalution 25'!H29 -> 3 | P39: =IF(COUNT(N39:O39)>0,AVERAGEIF(N39:O39,">=0"), IF(AND(ISNUMBER(D39),D39<=DATE(2025,12,31)),"NR","NA")) -> 3 | Q39: =AVERAGE(J39,M39,P39,) -> 2.25 | R39: =IF(P39="","", IF(OR(P39="NR",P39="NA"),"NA", IF(P39<3,"Poor", IF(P39<3.8,"Average","High") ))) -> Average | S39: =IFERROR( _xlfn.XLOOKUP(Q39,[2]Result!$A$7:$A$15,[2]Result!$C$7:$C$15,"Out of range",-1),"N/A") -> 2A | T39: =IF($D39>DATE(2023,12,31),"NA",IF(J39="","NR",J39)) -> 3 | U39: {=IF(OR(J39="NA",J39="NR",ISBLANK(J39)),J39,IFERROR(INDEX([2]Result!$C$7:$C$15,MATCH(1,(J39>=[2]Result!$A$7:$A$15)*(J39<=[2]Result!$B$7:$B$15),0)), "NA"))} -> 2B | V39: =IF($D39>DATE(2024,12,31),"NA",IF(M39="","NR",M39)) -> 3 | W39: {=IF(OR(M39="NA",M39="NR",ISBLANK(M39)),M39,IFERROR(INDEX([2]Result!$C$7:$C$15,MATCH(1,(M39>=[2]Result!$A$7:$A$15)*(M39<=[2]Result!$B$7:$B$15),0)), "NA"))} -> 2B
A40: 29 | B40: 10845 | C40: ='[2]Evalution 25'!B30 -> Angelica Villena | D40: 44297 | E40: ='[2]Evalution 25'!C30 -> Dubai | F40: ='[2]Evalution 25'!E30 -> Senior Traffic Operations | G40: ='[2]Evalution 25'!D30 -> Traffic | H40: ='[2]Evalutaion 23'!G22 -> 4.3 | I40: ='[2]Evalutaion 23'!H22 -> 4.8 | J40: =IF(COUNT(H40:I40)>0,AVERAGEIF(H40:I40,">=0"), IF(AND(ISNUMBER(D40),D40<=DATE(2023,12,31)),"NR","NA")) -> 4.55 | K40: ='[2]Evalutaion 24'!G25 -> 4.6 | L40: ='[2]Evalutaion 24'!H25 -> 4.7 | M40: =IF(COUNT(K40:L40)>0,AVERAGEIF(K40:L40,">=0"), IF(AND(ISNUMBER(D40),D40<=DATE(2024,12,31)),"NR","NA")) -> 4.65 | N40: ='[2]Evalution 25'!G30 -> 4.9 | O40: ='[2]Evalution 25'!H30 -> 4.8 | P40: =IF(COUNT(N40:O40)>0,AVERAGEIF(N40:O40,">=0"), IF(AND(ISNUMBER(D40),D40<=DATE(2025,12,31)),"NR","NA")) -> 4.85 | Q40: =AVERAGE(J40,M40,P40,) -> 3.5125 | R40: =IF(P40="","", IF(OR(P40="NR",P40="NA"),"NA", IF(P40<3,"Poor", IF(P40<3.8,"Average","High") ))) -> High | S40: =IFERROR( _xlfn.XLOOKUP(Q40,[2]Result!$A$7:$A$15,[2]Result!$C$7:$C$15,"Out of range",-1),"N/A") -> 2C | T40: =IF($D40>DATE(2023,12,31),"NA",IF(J40="","NR",J40)) -> 4.55 | U40: {=IF(OR(J40="NA",J40="NR",ISBLANK(J40)),J40,IFERROR(INDEX([2]Result!$C$7:$C$15,MATCH(1,(J40>=[2]Result!$A$7:$A$15)*(J40<=[2]Result!$B$7:$B$15),0)), "NA"))} -> NA | V40: =IF($D40>DATE(2024,12,31),"NA",IF(M40="","NR",M40)) -> 4.65 | W40: {=IF(OR(M40="NA",M40="NR",ISBLANK(M40)),M40,IFERROR(INDEX([2]Result!$C$7:$C$15,MATCH(1,(M40>=[2]Result!$A$7:$A$15)*(M40<=[2]Result!$B$7:$B$15),0)), "NA"))} -> 3C
A41: 30 | B41: 10312 | C41: ='[2]Evalution 25'!B31 -> Arlene Belleza Patrimonio | D41: 44171 | E41: ='[2]Evalution 25'!C31 -> Dubai | F41: ='[2]Evalution 25'!E31 -> Senior Traffic Executive | G41: ='[2]Evalution 25'!D31 -> Traffic | H41: ='[2]Evalutaion 23'!G23 -> 3.6 | I41: ='[2]Evalutaion 23'!H23 -> 3.5 | J41: =IF(COUNT(H41:I41)>0,AVERAGEIF(H41:I41,">=0"), IF(AND(ISNUMBER(D41),D41<=DATE(2023,12,31)),"NR","NA")) -> 3.55 | K41: ='[2]Evalutaion 24'!G26 -> 4 | L41: ='[2]Evalutaion 24'!H26 -> 4 | M41: =IF(COUNT(K41:L41)>0,AVERAGEIF(K41:L41,">=0"), IF(AND(ISNUMBER(D41),D41<=DATE(2024,12,31)),"NR","NA")) -> 4 | N41: ='[2]Evalution 25'!G31 -> 3.8 | O41: ='[2]Evalution 25'!H31 -> 3.8 | P41: =IF(COUNT(N41:O41)>0,AVERAGEIF(N41:O41,">=0"), IF(AND(ISNUMBER(D41),D41<=DATE(2025,12,31)),"NR","NA")) -> 3.8 | Q41: =AVERAGE(J41,M41,P41,) -> 2.8375 | R41: =IF(P41="","", IF(OR(P41="NR",P41="NA"),"NA", IF(P41<3,"Poor", IF(P41<3.8,"Average","High") ))) -> High | S41: =IFERROR( _xlfn.XLOOKUP(Q41,[2]Result!$A$7:$A$15,[2]Result!$C$7:$C$15,"Out of range",-1),"N/A") -> 2B | T41: =IF($D41>DATE(2023,12,31),"NA",IF(J41="","NR",J41)) -> 3.55 | U41: {=IF(OR(J41="NA",J41="NR",ISBLANK(J41)),J41,IFERROR(INDEX([2]Result!$C$7:$C$15,MATCH(1,(J41>=[2]Result!$A$7:$A$15)*(J41<=[2]Result!$B$7:$B$15),0)), "NA"))} -> NA | V41: =IF($D41>DATE(2024,12,31),"NA",IF(M41="","NR",M41)) -> 4 | W41: {=IF(OR(M41="NA",M41="NR",ISBLANK(M41)),M41,IFERROR(INDEX([2]Result!$C$7:$C$15,MATCH(1,(M41>=[2]Result!$A$7:$A$15)*(M41<=[2]Result!$B$7:$B$15),0)), "NA"))} -> 3A
A42: 31 | B42: 31254 | C42: ='[2]Evalution 25'!B32 -> Assaad Boujawdeh | D42: 44458 | E42: ='[2]Evalution 25'!C32 -> Riyadh | F42: ='[2]Evalution 25'!E32 -> Client Growth Senior Manager | G42: ='[2]Evalution 25'!D32 -> Client Growth | H42: ='[2]Evalutaion 23'!G24 -> 3.4 | I42: ='[2]Evalutaion 23'!H24 -> 3.3 | J42: =IF(COUNT(H42:I42)>0,AVERAGEIF(H42:I42,">=0"), IF(AND(ISNUMBER(D42),D42<=DATE(2023,12,31)),"NR","NA")) -> 3.35 | K42: ='[2]Evalutaion 24'!G27 -> 3.4 | L42: ='[2]Evalutaion 24'!H27 -> 3.8 | M42: =IF(COUNT(K42:L42)>0,AVERAGEIF(K42:L42,">=0"), IF(AND(ISNUMBER(D42),D42<=DATE(2024,12,31)),"NR","NA")) -> 3.6 | N42: ='[2]Evalution 25'!G32 -> 3.1 | O42: ='[2]Evalution 25'!H32 -> 3.8 | P42: =IF(COUNT(N42:O42)>0,AVERAGEIF(N42:O42,">=0"), IF(AND(ISNUMBER(D42),D42<=DATE(2025,12,31)),"NR","NA")) -> 3.45 | Q42: =AVERAGE(J42,M42,P42,) -> 2.6 | R42: =IF(P42="","", IF(OR(P42="NR",P42="NA"),"NA", IF(P42<3,"Poor", IF(P42<3.8,"Average","High") ))) -> Average | S42: =IFERROR( _xlfn.XLOOKUP(Q42,[2]Result!$A$7:$A$15,[2]Result!$C$7:$C$15,"Out of range",-1),"N/A") -> 2A | T42: =IF($D42>DATE(2023,12,31),"NA",IF(J42="","NR",J42)) -> 3.35 | U42: {=IF(OR(J42="NA",J42="NR",ISBLANK(J42)),J42,IFERROR(INDEX([2]Result!$C$7:$C$15,MATCH(1,(J42>=[2]Result!$A$7:$A$15)*(J42<=[2]Result!$B$7:$B$15),0)), "NA"))} -> 2C | V42: =IF($D42>DATE(2024,12,31),"NA",IF(M42="","NR",M42)) -> 3.6 | W42: {=IF(OR(M42="NA",M42="NR",ISBLANK(M42)),M42,IFERROR(INDEX([2]Result!$C$7:$C$15,MATCH(1,(M42>=[2]Result!$A$7:$A$15)*(M42<=[2]Result!$B$7:$B$15),0)), "NA"))} -> 3A
A43: 32 | B43: 47611 | C43: ='[2]Evalution 25'!B33 -> Cecille Ponsica Mago | D43: 45166 | E43: ='[2]Evalution 25'!C33 -> Dubai | F43: ='[2]Evalution 25'!E33 -> Office Attendant | G43: ='[2]Evalution 25'!D33 -> Admin | H43: ='[2]Evalutaion 23'!G25 -> 0 | I43: ='[2]Evalutaion 23'!H25 -> 4 | J43: =IF(COUNT(H43:I43)>0,AVERAGEIF(H43:I43,">=0"), IF(AND(ISNUMBER(D43),D43<=DATE(2023,12,31)),"NR","NA")) -> 2 | K43: ='[2]Evalutaion 24'!G28 -> 5 | L43: ='[2]Evalutaion 24'!H28 -> 4.5 | M43: =IF(COUNT(K43:L43)>0,AVERAGEIF(K43:L43,">=0"), IF(AND(ISNUMBER(D43),D43<=DATE(2024,12,31)),"NR","NA")) -> 4.75 | N43: ='[2]Evalution 25'!G33 -> 0 | O43: ='[2]Evalution 25'!H33 -> 4.2 | P43: =IF(COUNT(N43:O43)>0,AVERAGEIF(N43:O43,">=0"), IF(AND(ISNUMBER(D43),D43<=DATE(2025,12,31)),"NR","NA")) -> 2.1 | Q43: =AVERAGE(J43,M43,P43,) -> 2.2125 | R43: =IF(P43="","", IF(OR(P43="NR",P43="NA"),"NA", IF(P43<3,"Poor", IF(P43<3.8,"Average","High") ))) -> Poor | S43: =IFERROR( _xlfn.XLOOKUP(Q43,[2]Result!$A$7:$A$15,[2]Result!$C$7:$C$15,"Out of range",-1),"N/A") -> 2A | T43: =IF($D43>DATE(2023,12,31),"NA",IF(J43="","NR",J43)) -> 2 | U43: {=IF(OR(J43="NA",J43="NR",ISBLANK(J43)),J43,IFERROR(INDEX([2]Result!$C$7:$C$15,MATCH(1,(J43>=[2]Result!$A$7:$A$15)*(J43<=[2]Result!$B$7:$B$15),0)), "NA"))} -> 1C | V43: =IF($D43>DATE(2024,12,31),"NA",IF(M43="","NR",M43)) -> 4.75 | W43: {=IF(OR(M43="NA",M43="NR",ISBLANK(M43)),M43,IFERROR(INDEX([2]Result!$C$7:$C$15,MATCH(1,(M43>=[2]Result!$A$7:$A$15)*(M43<=[2]Result!$B$7:$B$15),0)), "NA"))} -> 3C
...

Sheet Grid_23
B12: 9 Grid Box 2023
P19: Zone | Q19: Professional Profile | R19: Description | S19: How To help this Employee to Grow
P20: 3A | Q20: Solid Performer | R20: High performance & limited potential | S20: Seasoned professional who is great at their current role but lacks ambition or drive to grow beyond role. Keep them happy and give them raises / bonuses / acknowledgements often.
M21: Location | P21: 3B | Q21: High Performer | R21: High performance & moderate potential | S21: Their current role may provide opportunity for growth & development. They may be too tactically focused; provide strategic thinking and raise their potential.
M22: Department | P22: 3C | Q22: Star | R22: High performance & high potential | S22: This is your superstar employee. This person consistently performs well in a variety of assignments, demonstrates strategic thinking, excellent problem-solver, and intrinsically motivated to excel. They are likely ready for a significant role and set of responsibilities.
P23: 2A | Q23: Average Performer | R23: Good performance & limited potential | S23: An effective performer, but may have reached their career potential. Coach this employee on becoming more innovative, and determine if they have potential in another part of the organization.
P24: 2B | Q24: Core Player | R24: Good performance & moderate potential | S24: This is your “B” team – the solid players that make up 80% of the capacity of a good organization. Keep these people happy, invest in them regularly, and make sure they have a feeling of ownership in the organization.
P25: 2C | Q25: Growth Employee | R25: Good performance & high potential | S25: This person is a solid candidate to continue to grow in their current vertical. Give them stretch goals to maximize their potential and keep them engaged.
P26: 1A | Q26: Risk | R26: Poor performance & limited potential | S26: This person is likely a candidate to be reassigned to a different role or exited from the company. Counsel this employee on their options going forward.
P27: 1B | Q27: Inconsistent Player | R27: Poor performance & moderate potential | S27: With coaching, this person could progress within their role. Focus on stretch goals for this employee.
P28: 1C | Q28: Potential Gem | R28: Poor performance & high potential | S28: This person is possibly a star, but may not be in the right role, or lacks the experience needed to be successful right now. Give them time to grow into their potential, along with counseling and support on their career planning.

Sheet Evalutaion 23
H2: Performance | K2: Potential Zone
B3: Potin | C3: High | D3: {=SUMPRODUCT(SUBTOTAL(103,OFFSET('Evalutaion 23'!$M$2,ROW('Evalutaion 23'!$M$2:$M$500)-ROW('Evalutaion 23'!$M$2),0))*('Evalutaion 23'!$M$2:$M$500="3A"))} -> 3 | E3: {=SUMPRODUCT(SUBTOTAL(103,OFFSET('Evalutaion 23'!$M$2,ROW('Evalutaion 23'!$M$2:$M$500)-ROW('Evalutaion 23'!$M$2),0))*('Evalutaion 23'!$M$2:$M$500="3B"))} -> 3 | F3: {=SUMPRODUCT(SUBTOTAL(103,OFFSET('Evalutaion 23'!$M$2,ROW('Evalutaion 23'!$M$2:$M$500)-ROW('Evalutaion 23'!$M$2),0))*('Evalutaion 23'!$M$2:$M$500="3C"))} -> 23 | H3: Poor | I3: 3.4 | K3: Low | L3: 3
C4: Medium | D4: {=SUMPRODUCT(SUBTOTAL(103,OFFSET('Evalutaion 23'!$M$2,ROW('Evalutaion 23'!$M$2:$M$500)-ROW('Evalutaion 23'!$M$2),0))*('Evalutaion 23'!$M$2:$M$500="2A"))} -> 30 | E4: {=SUMPRODUCT(SUBTOTAL(103,OFFSET('Evalutaion 23'!$M$2,ROW('Evalutaion 23'!$M$2:$M$500)-ROW('Evalutaion 23'!$M$2),0))*('Evalutaion 23'!$M$2:$M$500="2B"))} -> 52 | F4: {=SUMPRODUCT(SUBTOTAL(103,OFFSET('Evalutaion 23'!$M$2,ROW('Evalutaion 23'!$M$2:$M$500)-ROW('Evalutaion 23'!$M$2),0))*('Evalutaion 23'!$M$2:$M$500="2C"))} -> 5 | H4: Average | I4: 4.4 | K4: Medium | L4: 4.4
C5: Low | D5: {=SUMPRODUCT(SUBTOTAL(103,OFFSET('Evalutaion 23'!$M$2,ROW('Evalutaion 23'!$M$2:$M$500)-ROW('Evalutaion 23'!$M$2),0))*('Evalutaion 23'!$M$2:$M$500="1A"))} -> 2 | E5: {=SUMPRODUCT(SUBTOTAL(103,OFFSET('Evalutaion 23'!$M$2,ROW('Evalutaion 23'!$M$2:$M$500)-ROW('Evalutaion 23'!$M$2),0))*('Evalutaion 23'!$M$2:$M$500="1B"))} -> 0 | F5: {=SUMPRODUCT(SUBTOTAL(103,OFFSET('Evalutaion 23'!$M$2,ROW('Evalutaion 23'!$M$2:$M$500)-ROW('Evalutaion 23'!$M$2),0))*('Evalutaion 23'!$M$2:$M$500="1C"))} -> 0 | H5: High | K5: High
D6: Poor | E6: Average | F6: High
D7: Perf
A10: Employee Number | B10: Employee Name | C10: Joining Date | D10: Location | E10: Department | F10: Position | G10: App Line Manager | H10: Objectives and Competency Score | I10: Objectives Score | J10: Overall Competency Score | K10: Perforamnce Zone | L10: Potential Zone | M10: Gird Zone
A11: 31260 | B11: Abdulaziz Abdullah Abdulaziz Al Zehairi | C11: =_xlfn.XLOOKUP(A11,Table8[Employee Number],Table8[Joining Date],"") -> 29/12/2021 | D11: MMS KSA | E11: Admin | F11: Runner Driver | G11: Abdulmohsen Ibrahim Hamad Almubadel | H11: =AVERAGE(I11,J11) -> 5 | I11: 5 | J11: 5 | K11: =IF(H11="","", IF(OR(H11="NR",H11="NA"),"NA", IF(H11<$I$3,"Poor", IF(H11<$I$4,"Average","High") ))) -> High | L11: =IF(J11="","", IF(OR(J11="NR",J11="NA"),"NA", IF(J11<$L$3,"Low", IF(J11<$L$4,"Medium","High") ))) -> High | M11: =IF(OR(K11="",L11=""),"", IF(AND(K11=$H$5,L11=$K$5),"3C", IF(AND(K11=$H$4,L11=$K$5),"3B", IF(AND(K11=$H$3,L11=$K$5),"3A", IF(AND(K11=$H$5,L11=$K$4),"2C", IF(AND(K11=$H$4,L11=$K$4),"2B", IF(AND(K11=$H$3,L11=$K$4),"2A", IF(AND(K11=$H$5,L11=$K$3),"1C", IF(AND(K11=$H$4,L11=$K$3),"1B", IF(AND(K11=$H$3,L11=$K$3),"1A","") ))))))))) -> 3C
A12: 4756 | B12: Abdulkader Abbasbhai Sukhsarwala | C12: =_xlfn.XLOOKUP(A12,Table8[Employee Number],Table8[Joining Date],"") -> 01/01/2021 | D12: MMS UAE | E12: Client Growth | F12: Senior Digital Yield Analyst | G12: Jad Wajdi Saab | H12: =AVERAGE(I12,J12) -> 3.85 | I12: 3.9 | J12: 3.8 | K12: =IF(H12="","", IF(OR(H12="NR",H12="NA"),"NA", IF(H12<$I$3,"Poor", IF(H12<$I$4,"Average","High") ))) -> Average | L12: =IF(J12="","", IF(OR(J12="NR",J12="NA"),"NA", IF(J12<$L$3,"Low", IF(J12<$L$4,"Medium","High") ))) -> Medium | M12: =IF(OR(K12="",L12=""),"", IF(AND(K12=$H$5,L12=$K$5),"3C", IF(AND(K12=$H$4,L12=$K$5),"3B", IF(AND(K12=$H$3,L12=$K$5),"3A", IF(AND(K12=$H$5,L12=$K$4),"2C", IF(AND(K12=$H$4,L12=$K$4),"2B", IF(AND(K12=$H$3,L12=$K$4),"2A", IF(AND(K12=$H$5,L12=$K$3),"1C", IF(AND(K12=$H$4,L12=$K$3),"1B", IF(AND(K12=$H$3,L12=$K$3),"1A","") ))))))))) -> 2B
A13: 48121 | B13: Abdullah Mohammed Abutaleb | C13: =_xlfn.XLOOKUP(A13,Table8[Employee Number],Table8[Joining Date],"") -> 25/09/2023 | D13: MMS KSA | E13: Marketing | F13: Marketing Manager | G13: Layal Takieddine | H13: =AVERAGE(I13,J13) -> 3.35 | I13: 3 | J13: 3.7 | K13: =IF(H13="","", IF(OR(H13="NR",H13="NA"),"NA", IF(H13<$I$3,"Poor", IF(H13<$I$4,"Average","High") ))) -> Poor | L13: =IF(J13="","", IF(OR(J13="NR",J13="NA"),"NA", IF(J13<$L$3,"Low", IF(J13<$L$4,"Medium","High") ))) -> Medium | M13: =IF(OR(K13="",L13=""),"", IF(AND(K13=$H$5,L13=$K$5),"3C", IF(AND(K13=$H$4,L13=$K$5),"3B", IF(AND(K13=$H$3,L13=$K$5),"3A", IF(AND(K13=$H$5,L13=$K$4),"2C", IF(AND(K13=$H$4,L13=$K$4),"2B", IF(AND(K13=$H$3,L13=$K$4),"2A", IF(AND(K13=$H$5,L13=$K$3),"1C", IF(AND(K13=$H$4,L13=$K$3),"1B", IF(AND(K13=$H$3,L13=$K$3),"1A","") ))))))))) -> 2A
A14: 10848 | B14: Abir Kharsa | C14: =_xlfn.XLOOKUP(A14,Table8[Employee Number],Table8[Joining Date],"") -> 16/05/2021 | D14: MMS UAE | E14: Traffic | F14: Senior Traffic Executive | G14: Ahmed M M Omran | H14: =AVERAGE(I14,J14) -> 4.8 | I14: 4.6 | J14: 5 | K14: =IF(H14="","", IF(OR(H14="NR",H14="NA"),"NA", IF(H14<$I$3,"Poor", IF(H14<$I$4,"Average","High") ))) -> High | L14: =IF(J14="","", IF(OR(J14="NR",J14="NA"),"NA", IF(J14<$L$3,"Low", IF(J14<$L$4,"Medium","High") ))) -> High | M14: =IF(OR(K14="",L14=""),"", IF(AND(K14=$H$5,L14=$K$5),"3C", IF(AND(K14=$H$4,L14=$K$5),"3B", IF(AND(K14=$H$3,L14=$K$5),"3A", IF(AND(K14=$H$5,L14=$K$4),"2C", IF(AND(K14=$H$4,L14=$K$4),"2B", IF(AND(K14=$H$3,L14=$K$4),"2A", IF(AND(K14=$H$5,L14=$K$3),"1C", IF(AND(K14=$H$4,L14=$K$3),"1B", IF(AND(K14=$H$3,L14=$K$3),"1A","") ))))))))) -> 3C
A15: 6557 | B15: Adel Mohamed Adeeb Abou Elnasr Mohamed | C15: =_xlfn.XLOOKUP(A15,Table8[Employee Number],Table8[Joining Date],"") -> 01/06/2022 | D15: MMS Egypt | E15: Agency Partnerships | F15: Client Service Senior Supervisor | G15: Mahmoud Mohamed Mahmoud Gomaa | H15: =AVERAGE(I15,J15) -> 4.3 | I15: 4.3 | J15: 4.3 | K15: =IF(H15="","", IF(OR(H15="NR",H15="NA"),"NA", IF(H15<$I$3,"Poor", IF(H15<$I$4,"Average","High") ))) -> Average | L15: =IF(J15="","", IF(OR(J15="NR",J15="NA"),"NA", IF(J15<$L$3,"Low", IF(J15<$L$4,"Medium","High") ))) -> Medium | M15: =IF(OR(K15="",L15=""),"", IF(AND(K15=$H$5,L15=$K$5),"3C", IF(AND(K15=$H$4,L15=$K$5),"3B", IF(AND(K15=$H$3,L15=$K$5),"3A", IF(AND(K15=$H$5,L15=$K$4),"2C", IF(AND(K15=$H$4,L15=$K$4),"2B", IF(AND(K15=$H$3,L15=$K$4),"2A", IF(AND(K15=$H$5,L15=$K$3),"1C", IF(AND(K15=$H$4,L15=$K$3),"1B", IF(AND(K15=$H$3,L15=$K$3),"1A","") ))))))))) -> 2B
